<?xml version="1.0" encoding="utf-8"?>
<!-- This URDF was automatically created by SolidWorks to URDF Exporter! Originally created by Stephen Brawner (brawner@gmail.com) 
     Commit Version: 1.6.0-4-g7f85cfe  Build Version: 1.6.7995.38578
     For more information, please see http://wiki.ros.org/sw_urdf_exporter -->
<robot
  name="FRIDA">
  <link
    name="base_link">
    <inertial>
      <origin
        xyz="-0.0572325931675447 -0.00437678741979631 0.384343979057305"
        rpy="0 0 0" />
      <mass
        value="13.9552672276187" />
      <inertia
        ixx="0.387816129675932"
        ixy="-0.000166177926142373"
        ixz="-0.000583661776621432"
        iyy="0.34439433785987"
        iyz="-0.000132493833429814"
        izz="0.131300466770956" />
    </inertial>
    <visual>
      <origin
        xyz="0 0 0"
        rpy="0 0 0" />
      <geometry>
        <mesh
          filename="package://frida_description/urdf/meshes/base_link.STL" />
      </geometry>
      <material
        name="">
        <color
          rgba="0.792156862745098 0.819607843137255 0.933333333333333 1" />
      </material>
    </visual>
    <collision>
      <origin
        xyz="0 0 0"
        rpy="0 0 0" />
      <geometry>
        <mesh
          filename="package://frida_description/urdf/meshes/base_link.STL" />
      </geometry>
    </collision>
  </link>
  <link
    name="right_wheel">
    <inertial>
      <origin
        xyz="-0.1875 -0.034916320504547 0.256"
        rpy="0 0 0" />
      <mass
        value="0.528918539158378" />
      <inertia
        ixx="0.000631308353030454"
        ixy="4.50512202234995E-20"
        ixz="1.22382015150358E-21"
        iyy="0.000631308353030454"
        iyz="7.24830396865864E-21"
        izz="0.00112157176228534" />
    </inertial>
    <visual>
      <origin
        xyz="0 0 0"
        rpy="0 0 0" />
      <geometry>
        <mesh
          filename="package://frida_description/urdf/meshes/right_wheel.STL" />
      </geometry>
      <material
        name="">
        <color
          rgba="0.792156862745098 0.819607843137255 0.933333333333333 1" />
      </material>
    </visual>
    <collision>
      <origin
        xyz="0 0 0"
        rpy="0 0 0" />
      <geometry>
        <mesh
          filename="package://frida_description/urdf/meshes/right_wheel.STL" />
      </geometry>
    </collision>
  </link>
  <joint
    name="rightwheel"
    type="continuous">
    <origin
      xyz="0.11226 -0.09 0.0025837"
      rpy="-1.5708 0 0" />
    <parent
      link="base_link" />
    <child
      link="right_wheel" />
    <axis
      xyz="0 0 0" />
  </joint>
  <link
    name="left_wheel">
    <inertial>
      <origin
        xyz="-2.77555756156289E-17 0 -0.0389999999999999"
        rpy="0 0 0" />
      <mass
        value="0.528918539158378" />
      <inertia
        ixx="0.000631308353030454"
        ixy="4.50512202234995E-20"
        ixz="1.22382015150358E-21"
        iyy="0.000631308353030454"
        iyz="7.24830396865864E-21"
        izz="0.00112157176228534" />
    </inertial>
    <visual>
      <origin
        xyz="0 0 0"
        rpy="0 0 0" />
      <geometry>
        <mesh
          filename="package://frida_description/urdf/meshes/left_wheel.STL" />
      </geometry>
      <material
        name="">
        <color
          rgba="0.792156862745098 0.819607843137255 0.933333333333333 1" />
      </material>
    </visual>
    <collision>
      <origin
        xyz="0 0 0"
        rpy="0 0 0" />
      <geometry>
        <mesh
          filename="package://frida_description/urdf/meshes/left_wheel.STL" />
      </geometry>
    </collision>
  </link>
  <joint
    name="leftwheel"
    type="continuous">
    <origin
      xyz="-0.075244 0.205 0.0375"
      rpy="-1.5708 0 0" />
    <parent
      link="base_link" />
    <child
      link="left_wheel" />
    <axis
      xyz="0 0 0" />
  </joint>
  <link
    name="right_castwheel_bracket">
    <inertial>
      <origin
        xyz="1.38777878078145E-17 -4.16333634234434E-17 -0.0124453470278458"
        rpy="0 0 0" />
      <mass
        value="0.0167352759899297" />
      <inertia
        ixx="7.09247978055374E-06"
        ixy="3.14601801797092E-08"
        ixz="2.04305776379431E-21"
        iyy="7.5392977436896E-06"
        iyz="3.65635023764019E-21"
        izz="5.85653067123054E-06" />
    </inertial>
    <visual>
      <origin
        xyz="0 0 0"
        rpy="0 0 0" />
      <geometry>
        <mesh
          filename="package://frida_description/urdf/meshes/right_castwheel_bracket.STL" />
      </geometry>
      <material
        name="">
        <color
          rgba="0.792156862745098 0.819607843137255 0.933333333333333 1" />
      </material>
    </visual>
    <collision>
      <origin
        xyz="0 0 0"
        rpy="0 0 0" />
      <geometry>
        <mesh
          filename="package://frida_description/urdf/meshes/right_castwheel_bracket.STL" />
      </geometry>
    </collision>
  </link>
  <joint
    name="rightcastwheelbracket"
    type="continuous">
    <origin
      xyz="0.11226 -0.09 0.047"
      rpy="0 0 0" />
    <parent
      link="base_link" />
    <child
      link="right_castwheel_bracket" />
    <axis
      xyz="0 0 1" />
  </joint>
  <link
    name="right_cast_wheel">
    <inertial>
      <origin
        xyz="1.38777878078145E-17 1.30104260698261E-18 1.38777878078145E-17"
        rpy="0 0 0" />
      <mass
        value="0.0694291976443344" />
      <inertia
        ixx="1.95753930343808E-05"
        ixy="1.14883324033016E-21"
        ixz="8.56401854668578E-07"
        iyy="1.95153903045283E-05"
        iyz="1.68418630992032E-21"
        izz="3.17385697912527E-05" />
    </inertial>
    <visual>
      <origin
        xyz="0 0 0"
        rpy="0 0 0" />
      <geometry>
        <mesh
          filename="package://frida_description/urdf/meshes/right_cast_wheel.STL" />
      </geometry>
      <material
        name="">
        <color
          rgba="0.792156862745098 0.819607843137255 0.933333333333333 1" />
      </material>
    </visual>
    <collision>
      <origin
        xyz="0 0 0"
        rpy="0 0 0" />
      <geometry>
        <mesh
          filename="package://frida_description/urdf/meshes/right_cast_wheel.STL" />
      </geometry>
    </collision>
  </link>
  <joint
    name="rightcastwheel"
    type="continuous">
    <origin
      xyz="0 0 -0.044416"
      rpy="-1.5708 0 0" />
    <parent
      link="right_castwheel_bracket" />
    <child
      link="right_cast_wheel" />
    <axis
      xyz="0.069892 0 0.99755" />
  </joint>
  <link
    name="left_castwheel_bracket">
    <inertial>
      <origin
        xyz="2.77555756156289E-17 4.16333634234434E-17 -0.0124453470278457"
        rpy="0 0 0" />
      <mass
        value="0.0167352759899297" />
      <inertia
        ixx="7.10891957203296E-06"
        ixy="8.98057366551926E-08"
        ixz="-3.54367283535805E-22"
        iyy="7.52285795221037E-06"
        iyz="7.23783035983899E-22"
        izz="5.85653067123053E-06" />
    </inertial>
    <visual>
      <origin
        xyz="0 0 0"
        rpy="0 0 0" />
      <geometry>
        <mesh
          filename="package://frida_description/urdf/meshes/left_castwheel_bracket.STL" />
      </geometry>
      <material
        name="">
        <color
          rgba="0.792156862745098 0.819607843137255 0.933333333333333 1" />
      </material>
    </visual>
    <collision>
      <origin
        xyz="0 0 0"
        rpy="0 0 0" />
      <geometry>
        <mesh
          filename="package://frida_description/urdf/meshes/left_castwheel_bracket.STL" />
      </geometry>
    </collision>
  </link>
  <joint
    name="leftcastwheelbracket"
    type="continuous">
    <origin
      xyz="0.11226 0.09 0.047"
      rpy="0 0 0" />
    <parent
      link="base_link" />
    <child
      link="left_castwheel_bracket" />
    <axis
      xyz="0 0 1" />
  </joint>
  <link
    name="left_cast_wheel">
    <inertial>
      <origin
        xyz="0 1.30104260698261E-18 -2.77555756156289E-17"
        rpy="0 0 0" />
      <mass
        value="0.0694291976443345" />
      <inertia
        ixx="2.00229132911862E-05"
        ixy="4.42261592612662E-22"
        ixz="2.44467129533484E-06"
        iyy="1.95153903045283E-05"
        iyz="8.70182156766803E-22"
        izz="3.12910495344473E-05" />
    </inertial>
    <visual>
      <origin
        xyz="0 0 0"
        rpy="0 0 0" />
      <geometry>
        <mesh
          filename="package://frida_description/urdf/meshes/left_cast_wheel.STL" />
      </geometry>
      <material
        name="">
        <color
          rgba="0.792156862745098 0.819607843137255 0.933333333333333 1" />
      </material>
    </visual>
    <collision>
      <origin
        xyz="0 0 0"
        rpy="0 0 0" />
      <geometry>
        <mesh
          filename="package://frida_description/urdf/meshes/left_cast_wheel.STL" />
      </geometry>
    </collision>
  </link>
  <joint
    name="leftcastwheel"
    type="continuous">
    <origin
      xyz="0 0 -0.044416"
      rpy="-1.5708 0 0" />
    <parent
      link="left_castwheel_bracket" />
    <child
      link="left_cast_wheel" />
    <axis
      xyz="-0.20327 0 -0.97912" />
  </joint>

  <!-- LIDAR -->
  <link
    name="LIDAR">
    <inertial>
      <origin
        xyz="-1.38777878078145E-17 -3.38181918277552E-34 0.0125"
        rpy="0 0 0" />
      <mass
        value="0.0962112750161874" />
      <inertia
        ixx="3.44757068808005E-05"
        ixy="1.3254524700622E-52"
        ixz="-6.00991536754997E-37"
        iyy="3.44757068808005E-05"
        iyz="8.13422838622583E-38"
        izz="5.89294059474148E-05" />
    </inertial>
    <visual>
      <origin
        xyz="0 0 0"
        rpy="0 0 0" />
      <geometry>
        <mesh
          filename="package://frida_description/urdf/meshes/LIDAR.STL" />
      </geometry>
      <material
        name="">
        <color
          rgba="0.101960784313725 0.101960784313725 0.101960784313725 1" />
      </material>
    </visual>
    <collision>
      <origin
        xyz="0 0 0"
        rpy="0 0 0" />
      <geometry>
        <mesh
          filename="package://frida_description/urdf/meshes/LIDAR.STL" />
      </geometry>
    </collision>
  </link>
  <joint
    name="lidar"
    type="fixed">
    <origin
      xyz="0.15026 0 0.117"
      rpy="0 0 0" />
    <parent
      link="base_link" />
    <child
      link="LIDAR" />
    <axis
      xyz="0 0 0" />
  </joint>
  <link
    name="intel_realsense">
    <inertial>
      <origin
        xyz="0.0121701331262114 -3.72379122319091E-07 -4.81694330181082E-05"
        rpy="0 0 0" />
      <mass
        value="0.0482013986778834" />
      <inertia
        ixx="2.73914552603833E-05"
        ixy="-4.25989861663579E-07"
        ixz="7.54926296247901E-09"
        iyy="3.35061197196779E-06"
        iyz="2.11610728670355E-09"
        izz="2.66521455986821E-05" />
    </inertial>
    <visual>
      <origin
        xyz="0 0 0"
        rpy="0 0 0" />
      <geometry>
        <mesh
          filename="package://frida_description/urdf/meshes/intel_realsense.STL" />
      </geometry>
      <material
        name="">
        <color
          rgba="0.776470588235294 0.756862745098039 0.737254901960784 1" />
      </material>
    </visual>
    <collision>
      <origin
        xyz="0 0 0"
        rpy="0 0 0" />
      <geometry>
        <mesh
          filename="package://frida_description/urdf/meshes/intel_realsense.STL" />
      </geometry>
    </collision>
  </link>
  <joint
    name="intelrealsense"
    type="fixed">
    <origin
      xyz="0.06478 0 0.55626"
      rpy="0 0 0" />
    <parent
      link="base_link" />
    <child
      link="intel_realsense" />
    <axis
      xyz="0 0 0" />
  </joint>

  <!-- Xarm -->
  <link
    name="Xarm">
    <inertial>
      <origin
        xyz="-0.0818970512692916 -0.000281576154793191 0.409928734746142"
        rpy="0 0 0" />
      <mass
        value="12.1997965903631" />
      <inertia
        ixx="0.0402826194516468"
        ixy="-0.000727395368951641"
        ixz="0.00492880975124087"
        iyy="0.0487377516768438"
        iyz="0.00375778475081379"
        izz="0.0320076363638461" />
    </inertial>
    <visual>
      <origin
        xyz="0 0 0"
        rpy="0 0 0" />
      <geometry>
        <mesh
          filename="package://frida_description/urdf/meshes/Xarm.STL" />
      </geometry>
      <material
        name="">
        <color
          rgba="0.752941176470588 0.752941176470588 0.752941176470588 1" />
      </material>
    </visual>
    <collision>
      <origin
        xyz="0 0 0"
        rpy="0 0 0" />
      <geometry>
        <mesh
          filename="package://frida_description/urdf/meshes/Xarm.STL" />
      </geometry>
    </collision>
  </link>
  <joint
    name="xarm"
    type="fixed">
    <origin
      xyz="0.0049756 0 0.455"
      rpy="0 0 0" />
    <parent
      link="base_link" />
    <child
      link="Xarm" />
    <axis
      xyz="0 0 0" />
  </joint>
</robot>