<?xml version="1.0"?>
<robot xmlns:xacro="http://www.ros.org/wiki/xacro" name="FRIDA">

<!-- Properties -->
<xacro:property name="mesh_path" value="package://frida_description/urdf/meshes/" />
<xacro:property name="material_rgba" value="0.792 0.820 0.933 1" />
<xacro:property name="lidar_rgba" value="0.102 0.102 0.102 1" />
<xacro:property name="intel_rgba" value="0.776 0.757 0.737 1" />

  <!-- Base Link -->
  <link name="base_link">
    <inertial>
      <origin xyz="-0.0572325931675447 -0.00437678741979631 0.384343979057305" rpy="0 0 0" />
      <mass value="13.9552672276187" />
      <inertia ixx="0.387816129675932" ixy="-0.000166177926142373" ixz="-0.000583661776621432" 
               iyy="0.34439433785987" iyz="-0.000132493833429814" izz="0.131300466770956" />
    </inertial>
    <visual>
      <origin xyz="0 0 0" rpy="0 0 0" />
      <geometry>
        <mesh filename="${mesh_path}base_link.STL" />
      </geometry>
      <material name="">
        <color rgba="${material_rgba}" />
      </material>
    </visual>
    <collision>
      <origin xyz="0 0 0" rpy="0 0 0" />
      <geometry>
        <mesh filename="${mesh_path}base_link.STL" />
      </geometry>
    </collision>
  </link>

  <!-- Right Wheel -->
  <link name="right_wheel">
    <inertial>
      <origin xyz="-0.1875 -0.034916320504547 0.256" rpy="0 0 0" />
      <mass value="0.528918539158378" />
      <inertia ixx="0.000631308353030454" ixy="4.50512202234995E-20" ixz="1.22382015150358E-21" 
               iyy="0.000631308353030454" iyz="7.24830396865864E-21" izz="0.00112157176228534" />
    </inertial>
    <visual>
      <origin xyz="0 0 0" rpy="0 0 0" />
      <geometry>
        <mesh filename="${mesh_path}right_wheel.STL" />
      </geometry>
      <material name="">
        <color rgba="${material_rgba}" />
      </material>
    </visual>
    <collision>
      <origin xyz="0 0 0" rpy="0 0 0" />
      <geometry>
        <mesh filename="${mesh_path}right_wheel.STL" />
      </geometry>
    </collision>
  </link>

  <joint name="rightwheel" type="continuous">
    <origin xyz="0.11226 -0.09 0.0025837" rpy="-1.5708 0 0" />
    <parent link="base_link" />
    <child link="right_wheel" />
    <axis xyz="0 0 0" />
  </joint>

  <!-- Left Wheel -->
  <link name="left_wheel">
    <inertial>
      <origin xyz="-0.1875 0.034916320504547 0.256" rpy="0 0 0" />
      <mass value="0.528918539158378" />
      <inertia ixx="0.000631308353030454" ixy="-4.50512202234995E-20" ixz="-1.22382015150358E-21" 
               iyy="0.000631308353030454" iyz="-7.24830396865864E-21" izz="0.00112157176228534" />
    </inertial>
    <visual>
      <origin xyz="0 0 0" rpy="0 0 0" />
      <geometry>
        <mesh filename="${mesh_path}left_wheel.STL" />
      </geometry>
      <material name="">
        <color rgba="${material_rgba}" />
      </material>
    </visual>
    <collision>
      <origin xyz="0 0 0" rpy="0 0 0" />
      <geometry>
        <mesh filename="${mesh_path}left_wheel.STL" />
      </geometry>
    </collision>
  </link>

  <joint name="leftwheel" type="continuous">
    <origin xyz="0.11226 0.09 0.0025837" rpy="-1.5708 0 0" />
    <parent link="base_link" />
    <child link="left_wheel" />
    <axis xyz="0 0 0" />
  </joint>

  <!-- RealSense Camera -->
  <link name="camera_link">
    <visual>
      <origin xyz="0.0 0.0 0.5" rpy="0 0 0" />
      <geometry>
        <mesh filename="${mesh_path}camera.STL" />
      </geometry>
      <material name="">
        <color rgba="${intel_rgba}" />
      </material>
    </visual>
  </link>

  <joint name="camera_joint" type="fixed">
    <origin xyz="0.0 0.0 0.5" rpy="0 0 0" />
    <parent link="base_link" />
    <child link="camera_link" />
  </joint>

  <!-- Lidar Sensor -->
  <link name="lidar_link">
    <visual>
      <origin xyz="0.0 0.0 0.4" rpy="0 0 0" />
      <geometry>
        <mesh filename="${mesh_path}lidar.STL" />
      </geometry>
      <material name="">
        <color rgba="${lidar_rgba}" />
      </material>
    </visual>
  </link>

  <joint name="lidar_joint" type="fixed">
    <origin xyz="0.0 0.0 0.4" rpy="0 0 0" />
    <parent link="base_link" />
    <child link="lidar_link" />
  </joint>

</robot>